Workbook

Sheet CASE 2
A1: Order_ID | B1: Order_Day | C1: Category | D1: Product | E1: Customer_Type | F1: Payment_Method | G1: Units | H1: Unit_Price | I1: Discount_Pct | J1: Shipping_Fee | K1: Total_Sales
A2: O2014 | B2: 15 | C2: Electronics | D2: SSD | E2: New | F2: Bank | G2: 3 | H2: 650 | I2: 0 | J2: 80 | K2: 2030
A3: O2007 | B3: 8 | C3: Software | D3: USB Drive | E3: New | F3: Bank | G3: 3 | H3: 250 | I3: 0 | J3: 0 | K3: 750
A4: O2001 | B4: 2 | C4: Accessories | D4: Headset | E4: Returning | F4: Bank | G4: 4 | H4: 1200 | I4: 0 | J4: 50 | K4: 4850
A5: O2000 | B5: 1 | C5: Software | D5: SSD | E5: Returning | F5: Bank | G5: 1 | H5: 650 | I5: 0 | J5: 50 | K5: 700
A6: O2022 | B6: 23 | C6: Software | D6: Webcam | E6: Returning | F6: Bank | G6: 3 | H6: 1800 | I6: 0 | J6: 0 | K6: 5400
A7: O2046 | B7: 47 | C7: Gadgets | D7: SSD | E7: New | F7: Card | G7: 3 | H7: 250 | I7: 0 | J7: 50 | K7: 800
A8: O2025 | B8: 26 | C8: Software | D8: SSD | E8: New | F8: Card | G8: 1 | H8: 650 | I8: 0 | J8: 80 | K8: 730
A9: O2049 | B9: 50 | C9: Software | D9: SSD | E9: New | F9: COD | G9: 1 | H9: 900 | I9: 0 | J9: 100 | K9: 1000
A10: O2035 | B10: 36 | C10: Accessories | D10: USB Drive | E10: Returning | F10: COD | G10: 4 | H10: 450 | I10: 0 | J10: 80 | K10: 1880
A11: O2037 | B11: 38 | C11: Software | D11: Webcam | E11: Returning | F11: COD | G11: 4 | H11: 900 | I11: 0 | J11: 50 | K11: 3650
A12: O2023 | B12: 24 | C12: Accessories | D12: Mouse | E12: New | F12: GCash | G12: 4 | H12: 1800 | I12: 0 | J12: 50 | K12: 7250
A13: O2009 | B13: 10 | C13: Accessories | D13: SSD | E13: Returning | F13: GCash | G13: 1 | H13: 250 | I13: 0 | J13: 80 | K13: 330
... A51: O2032 | B51: 33 | C51: Gadgets | D51: SSD | E51: Returning | F51: GCash | G51: 3 | H51: 1200 | I51: 15 | J51: 80 | K51: 3140

Sheet ANSWER
A1: CASTRO, JHAY L. | H1: 4TH YEAR SET A
A2: CASE STUDY NUMBER 2 ONLINE STORE SALES ANALYSIS
A3: TASK 1 & 2
A4: The raw dataset contains exactly 50 rows. There are 0 missing or invalid values, and 0 duplicate Order IDs. The data is clean and ready for analysis.
A6: TASK 3
A7: TOTAL: | B7: =SUM('CASE 2'!K2:K51) -> 86680
A8: MEAN: | B8: =AVERAGE('CASE 2'!K2:K51) -> 1733.6
A9: MEDIAN: | B9: =MEDIAN('CASE 2'!K2:K51) -> 1570
A10: MINIMUM: | B10: =MIN('CASE 2'!K2:K51) -> 287.5
A11: MAXIMUM: | B11: =MAX('CASE 2'!K2:K51) -> 7250
A13: TASK 4
A14: TOTAL UNIT SOLD: | C14: =SUM('CASE 2'!G2:G51) -> 123
A15: AVERAGE PER ORDER: | C15: =AVERAGE('CASE 2'!G2:G51) -> 2.46
A17: TASK 5 (PRODUCT CATEGORY)
A18: CATEGORY | B18: TOTAL SALES | C18: NO. OF ORDER
A19: ='CASE 2'!C2 -> Electronics | B19: =SUM('CASE 2'!K2:K12) -> 29040 | C19: =COUNTA('CASE 2'!C2:C12) -> 11
A20: ='CASE 2'!C13 -> Accessories | B20: =SUM('CASE 2'!K13:K19) -> 6612.5 | C20: =COUNTA('CASE 2'!C13:C19) -> 7
A21: ='CASE 2'!C20 -> Gadgets | B21: =SUM('CASE 2'!K20:K31) -> 19440 | C21: =COUNTA('CASE 2'!C20:C31) -> 12
A22: ='CASE 2'!C47 -> Software | B22: =SUM('CASE 2'!K32:K51) -> 31587.5 | C22: =COUNTA('CASE 2'!C32:C51) -> 20
A24: TASK 6
A25: PRODUCT | B25: SALES | C25: UNIT SOLD
A26: ='CASE 2'!D2 -> SSD | B26: =SUM('CASE 2'!K2:K6) -> 13730 | C26: =SUM('CASE 2'!H2:H6) -> 4550
A27: ='CASE 2'!D7 -> SSD | B27: =SUM('CASE 2'!K7:K13) -> 15640 | C27: =SUM('CASE 2'!G7:G13) -> 18
A28: ='CASE 2'!D14 -> Webcam | B28: =SUM('CASE 2'!K14:K17) -> 4205 | C28: =SUM('CASE 2'!G14:G17) -> 6
A29: ='CASE 2'!D18 -> USB Drive | B29: =SUM('CASE 2'!K18:K30) -> 19187.5 | C29: =SUM('CASE 2'!G18:G30) -> 29
A30: ='CASE 2'!D31 -> Headset | B30: =SUM('CASE 2'!K31:K41) -> 14365 | C30: =SUM('CASE 2'!G31:G41) -> 27
A31: ='CASE 2'!D42 -> USB Drive | B31: =SUM('CASE 2'!K42:K51) -> 19552.5 | C31: =SUM('CASE 2'!G42:G51) -> 29
A32: HIGHEST NUMBER OF SALES | C32: 21107.5
A33: HIGHEST NUMBER OF SOLD UNIT | C33: 33
A35: TASK 7
A36: CUSTOMER TYPE | B36: NO. OF ORDERS | C36: AVERAGE SALES | D36: TOTAL SALES
A37: NEW CUSTOMERS | B37: =COUNTA('CASE 2'!E2:E24) -> 23 | C37: =AVERAGE('CASE 2'!K2:K24) -> 1903.587 | D37: =SUM('CASE 2'!K2:K24) -> 43782.5
A38: RETURNING CUSTOMERS | B38: =COUNTA('CASE 2'!E25:E51) -> 27 | C38: =AVERAGE('CASE 2'!K25:K51) -> 1588.7963 | D38: =SUM('CASE 2'!K25:K51) -> 42897.5
A40: TASK 8
A41: PAYMENT METHOD | B41: NO. OF ORDERS | C41: TOTAL SALES
A42: ='CASE 2'!F2 -> Bank | B42: =COUNTA('CASE 2'!F2:F18) -> 17 | C42: =SUM('CASE 2'!K2:K18) -> 35335
A43: ='CASE 2'!F19 -> Bank | B43: =COUNTA('CASE 2'!F19:F26) -> 8 | C43: =SUM('CASE 2'!K19:K26) -> 11207.5
A44: ='CASE 2'!F27 -> COD | B44: =COUNTA('CASE 2'!F27:F40) -> 14 | C44: =SUM('CASE 2'!K27:K40) -> 18730
A45: ='CASE 2'!F41 -> GCash | B45: =COUNTA('CASE 2'!F41:F51) -> 11 | C45: =SUM('CASE 2'!K41:K51) -> 21407.5
A47: TASK 9
...
